2023-03-06 00:03:48,695 ERROR Internal Server Error: /accounts/google/login/ C:\py\D13_News\venv\Lib\site-packages\django\utils\log.py (<class 'allauth.socialaccount.models.SocialApp.DoesNotExist'>, DoesNotExist('SocialApp matching query does not exist.'), <traceback object at 0x000002A8BC62CC80>)
Traceback (most recent call last):
  File "C:\py\D13_News\venv\Lib\site-packages\django\core\handlers\exception.py", line 55, in inner
    response = get_response(request)
               ^^^^^^^^^^^^^^^^^^^^^
  File "C:\py\D13_News\venv\Lib\site-packages\django\core\handlers\base.py", line 197, in _get_response
    response = wrapped_callback(request, *callback_args, **callback_kwargs)
               ^^^^^^^^^^^^^^^^^^^^^^^^^^^^^^^^^^^^^^^^^^^^^^^^^^^^^^^^^^^^
  File "C:\py\D13_News\venv\Lib\site-packages\allauth\socialaccount\providers\oauth2\views.py", line 81, in view
    return self.dispatch(request, *args, **kwargs)
           ^^^^^^^^^^^^^^^^^^^^^^^^^^^^^^^^^^^^^^^
  File "C:\py\D13_News\venv\Lib\site-packages\allauth\socialaccount\providers\base\mixins.py", line 19, in dispatch
    return self.login(request, *args, **kwargs)
           ^^^^^^^^^^^^^^^^^^^^^^^^^^^^^^^^^^^^
  File "C:\py\D13_News\venv\Lib\site-packages\allauth\socialaccount\providers\oauth2\views.py", line 109, in login
    app = provider.get_app(self.request)
          ^^^^^^^^^^^^^^^^^^^^^^^^^^^^^^
  File "C:\py\D13_News\venv\Lib\site-packages\allauth\socialaccount\providers\base\provider.py", line 30, in get_app
    return adapter.get_app(request, self.id, config=config)
           ^^^^^^^^^^^^^^^^^^^^^^^^^^^^^^^^^^^^^^^^^^^^^^^^
  File "C:\py\D13_News\venv\Lib\site-packages\allauth\socialaccount\adapter.py", line 204, in get_app
    app = SocialApp.objects.get_current(provider, request)
          ^^^^^^^^^^^^^^^^^^^^^^^^^^^^^^^^^^^^^^^^^^^^^^^^
  File "C:\py\D13_News\venv\Lib\site-packages\allauth\socialaccount\models.py", line 31, in get_current
    app = self.get(sites__id=site.id, provider=provider)
          ^^^^^^^^^^^^^^^^^^^^^^^^^^^^^^^^^^^^^^^^^^^^^^
  File "C:\py\D13_News\venv\Lib\site-packages\django\db\models\manager.py", line 85, in manager_method
    return getattr(self.get_queryset(), name)(*args, **kwargs)
           ^^^^^^^^^^^^^^^^^^^^^^^^^^^^^^^^^^^^^^^^^^^^^^^^^^^
  File "C:\py\D13_News\venv\Lib\site-packages\django\db\models\query.py", line 650, in get
    raise self.model.DoesNotExist(
allauth.socialaccount.models.SocialApp.DoesNotExist: SocialApp matching query does not exist.
2023-03-06 00:03:48,702 ERROR "POST /accounts/google/login/?process=login HTTP/1.1" 500 105672 C:\py\D13_News\venv\Lib\site-packages\django\core\servers\basehttp.py None
